Workbook
Name Slicer_City: #N/A
Name Slicer_Status: #N/A

Sheet Raw CRM Dump
A1: Lead ID | B1: Agent Name | C1: Lead Source | D1: Phone Number | E1: Email | F1: Lead Date | G1: Status | H1: City | I1: Follow-up Done | J1: Remarks
A2: LD0364 | B2: R.Singh | C2: Referral | D2: +919804436995 | E2: rohit.singh66@gmail.com | F2: 03/01/2024 | G2: Converted | H2: Chennai | I2: Yes | J2: Demo done
A3: LD0224 | B3: K.Patel | C3: Meta Ads | E3: karan.patel32@gmail.com | F3: 19-01-2024 | G3: Converted | H3: Pune | I3: No | J3: Wrong number
A4: LD0303 | B4: Anjali Gupta | D4: N/A | E4: anjali.gupta71@gmail.com | F4: 02/27/2024 | G4: converted | H4: Pune | J4: Price issue
A5: LD0087 | B5: A.Gupta | C5: Google Ads | D5: +919345581223 | E5: anjali.gupta9@gmail.com | F5: 23 Feb 2024 | G5: open | H5: Indore | I5: Yes | J5: Demo done
A6: LD0319 | B6: Rohit S | C6: IVR | E6: rohit.singh29@gmail.com | F6: 03/03/2024 | G6: Not Interested | H6: Mumbai | I6: no | J6: Closed deal
A7: LD0049 | B7: R.Singh | C7: Meta Ads | D7: N/A | F7: 2024-02-18 | G7: Callback | H7: Chennai
A8: LD0342 | B8: karan patel | C8: Google Ads | D8: 90805-31003 | E8: karan.patel31@gmail.com | F8: 17 Jan 2024 | G8: Converted | H8: Pune | I8: no | J8: Price issue
A9: LD0115 | B9: D.Nair | C9: Walk-in | E9: divya.nair81@gmail.com | F9: 01-02-2024 | G9: Not Interested | H9: Delhi | J9: Interested
A10: LD0386 | B10: Divya N | C10: Google Ads | D10: +919506716572 | E10: divya.nair84@gmail.com | F10: 04 Feb 2024 | G10: converted | H10: Hyderabad | I10: yes | J10: Demo done
A11: LD0474 | B11: Priya M | C11: Meta Ads | D11: 99965-07527 | E11: priya.mehta36@gmail.com | F11: 2024-03-17 | G11: Open | H11: Pune | I11: Yes | J11: Demo done
A12: LD0097 | B12: Rohit S | C12: Meta Ads | E12: rohit.singh68@gmail.com | F12: 14 Feb 2024 | G12: open | H12: Jaipur | I12: yes | J12: Price issue
A13: LD0096 | B13: K.Patel | C13: Meta Ads | D13: 919182337498 | F13: 2024-01-25 | G13: Callback | H13: Hyderabad | I13: Yes | J13: Wrong number
A14: LD0009 | B14: amit verma | D14: +919842710947 | F14: 2024-01-07 | G14: converted | H14: Delhi | I14: no | J14: Follow up pending
A15: LD0111 | B15: Priya Metha | C15: Google Ads | D15: 919294131869 | E15: priya.mehta67@gmail.com | F15: 18 Feb 2024 | G15: converted | H15: Indore | I15: yes | J15: Interested
A16: LD0069 | B16: P.Mehta | C16: Referral | E16: priya.mehta30@gmail.com | F16: 2024-02-06 | G16: converted | I16: No | J16: Price issue
A17: LD0155 | B17: sneha joshi | D17: +91-9242102499 | E17: sneha.joshi39@gmail.com | F17: 30 Mar 2024 | G17: Not Interested | H17: Jaipur | I17: no | J17: Call back tomorrow
A18: LD0377 | B18: rahul sharma | C18: IVR | D18: N/A | E18: rahul.sharma84@gmail.com | F18: 2024-02-26 | G18: Lost | H18: Indore | I18: N | J18: Follow up pending
A19: LD0199 | B19: priya mehta | C19: Referral | D19: +919125674680 | E19: N/A | F19: 2024-02-02 | G19: Converted | H19: Indore | J19: Wrong number
A20: LD0177 | B20: Rahul Sharma | C20: Organic | D20: +91-9038597703 | E20: rahul.sharma57@gmail.com | F20: 30 Mar 2024 | G20: Converted | I20: N | J20: Demo done
A21: LD0490 | B21: amit verma | C21: IVR | E21: amit.verma61@gmail.com | F21: 01 Feb 2024 | G21: Lost | H21: Bangalore | J21: Call back tomorrow
A22: LD0371 | B22: karan patel | D22: 919404499727 | E22: karan.patel98@gmail.com | F22: 10 Mar 2024 | G22: converted | H22: Pune | I22: N | J22: Demo done
A23: LD0119 | B23: R.Singh | C23: Organic | D23: 919576627028 | F23: 26-02-2024 | G23: converted | I23: No
A24: LD0379 | B24: Amit Verma | C24: Referral | D24: 9961586578 | E24: amit.verma88@gmail.com | F24: 02/06/2024 | G24: Converted | H24: Delhi | J24: Call back tomorrow
A25: LD0352 | B25: A.Gupta | C25: Google Ads | D25: +919504556238 | E25: anjali.gupta22@gmail.com | F25: 23-01-2024 | G25: CONVERTED | H25: Pune | I25: no | J25: Not picking up
A26: LD0365 | B26: sneha joshi | C26: Organic | D26: +91-9074821759 | E26: sneha.joshi33@gmail.com | F26: 2024-02-28 | G26: Callback | H26: Jaipur | I26: Yes | J26: Demo done
A27: LD0408 | B27: Rohit Singh | C27: Referral | D27: N/A | E27: rohit.singh46@gmail.com | F27: 01/29/2024 | G27: Not Interested | H27: Bangalore | I27: N | J27: Call back tomorrow
A28: LD0362 | B28: R.Sharma | C28: Google Ads | D28: N/A | E28: rahul.sharma68@gmail.com | F28: 2024-03-05 | G28: Lost | H28: Jaipur | J28: Price issue
A29: LD0457 | B29: Divya Nair | C29: Google Ads | D29: 9368516048 | E29: divya.nair87@gmail.com | F29: 03 Feb 2024 | G29: open | H29: Pune | I29: no | J29: Interested
A30: LD0341 | B30: D.Nair | C30: Walk-in | D30: 9461200471 | E30: divya.nair50@gmail.com | F30: 2024-02-28 | G30: CONVERTED | H30: Bangalore | I30: no | J30: Call back tomorrow
A31: LD0447 | B31: Anjali G | C31: Referral | E31: anjali.gupta25@gmail.com | F31: 16 Jan 2024 | G31: Converted | H31: Mumbai | I31: Yes | J31: Closed deal
A32: LD0133 | B32: S.Joshi | C32: Meta Ads | D32: +91-9839335290 | F32: 2024-01-17 | G32: Lost | H32: Mumbai | I32: No | J32: Interested
A33: LD0482 | B33: D.Nair | C33: Google Ads | D33: N/A | E33: divya.nair58@gmail.com | F33: 03/05/2024 | G33: Open | H33: Hyderabad | I33: no | J33: Interested
A34: LD0417 | B34: rahul sharma | C34: Organic | D34: +91-9771159212 | E34: rahul.sharma92@gmail.com | F34: 11 Feb 2024 | G34: Not Interested | H34: Indore | I34: Yes | J34: Call back tomorrow
A35: LD0202 | B35: sneha joshi | C35: Meta Ads | D35: +91-9576615654 | E35: sneha.joshi61@gmail.com | F35: 09-01-2024 | G35: Converted | H35: Delhi | I35: N | J35: Closed deal
A36: LD0397 | B36: Amit Verma | D36: +91-9851656049 | E36: amit.verma28@gmail.com | F36: 20 Jan 2024 | G36: Callback | H36: Chennai | J36: Wrong number
A37: LD0430 | B37: Divya Nair | C37: IVR | D37: 96899-80940 | E37: divya.nair44@gmail.com | F37: 14-02-2024 | G37: Lost | H37: Indore | I37: Yes | J37: Not picking up
A38: LD0324 | B38: Rahul Sharma | C38: Meta Ads | D38: 9675254599 | F38: 20-03-2024 | G38: Converted | H38: Indore | I38: no | J38: Follow up pending
A39: LD0152 | B39: rohit singh | C39: IVR | D39: 95614-97840 | E39: rohit.singh1@gmail.com | F39: 2024-01-27 | G39: Callback | H39: Hyderabad | I39: yes | J39: Closed deal
A40: LD0060 | B40: Priya Mehta | C40: Organic | D40: N/A | E40: priya.mehta59@gmail.com | F40: 2024-01-10 | G40: CONVERTED | H40: Indore | I40: yes | J40: Call back tomorrow
...

Sheet Cleaned Data
A1: Lead ID | B1: Agent Name | C1: Lead Source | D1: Phone Number | E1: Email | F1: Lead Date | G1: Status | H1: City | I1: Follow-up Done | J1: Remarks
A2: LD0364 | B2: R.Singh | C2: Referral | D2: 9804436995 | E2: rohit.singh66@gmail.com | F2: 03-Jan-2024 | G2: Converted | H2: Chennai | I2: Yes | J2: Demo done
A3: LD0224 | B3: Karan Patel | C3: Meta Ads | E3: karan.patel32@gmail.com | F3: 19-Jan-2024 | G3: Converted | H3: Pune | I3: No | J3: Wrong number
A4: LD0303 | B4: Anjali Gupta | C4: Google Ads | E4: anjali.gupta71@gmail.com | F4: 27-Feb-2024 | G4: Converted | H4: Pune | J4: Price issue
A5: LD0087 | B5: A.Gupta | C5: Google Ads | D5: 9345581223 | E5: anjali.gupta9@gmail.com | F5: 23-Feb-2024 | G5: Open | H5: Indore | I5: Yes | J5: Demo done
A6: LD0319 | B6: Rohit Singh | C6: IVR | E6: rohit.singh29@gmail.com | F6: 03-Mar-2024 | G6: Not Interested | H6: Mumbai | I6: No | J6: Closed deal
A7: LD0049 | B7: R.Singh | C7: Meta Ads | F7: 18-Feb-2024 | G7: Callback | H7: Chennai
A8: LD0342 | B8: Karan Patel | C8: Google Ads | D8: 9080531003 | E8: karan.patel31@gmail.com | F8: 17-Jan-2024 | G8: Converted | H8: Pune | I8: No | J8: Price issue
A9: LD0115 | B9: Divya Nair | C9: Walk-in | E9: divya.nair81@gmail.com | F9: 01-Feb-2024 | G9: Not Interested | H9: Delhi | J9: Interested
A10: LD0386 | B10: Divya Nair | C10: Google Ads | D10: 9506716572 | E10: divya.nair84@gmail.com | F10: 04-Feb-2024 | G10: Converted | H10: Hyderabad | I10: Yes | J10: Demo done
A11: LD0474 | B11: Priya Mehta | C11: Meta Ads | D11: 9996507527 | E11: priya.mehta36@gmail.com | F11: 17-Mar-2024 | G11: Open | H11: Pune | I11: Yes | J11: Demo done
A12: LD0097 | B12: Rohit Singh | C12: Meta Ads | E12: rohit.singh68@gmail.com | F12: 14-Feb-2024 | G12: Open | H12: Jaipur | I12: Yes | J12: Price issue
A13: LD0096 | B13: Karan Patel | C13: Meta Ads | D13: 9182337498 | F13: 25-Jan-2024 | G13: Callback | H13: Hyderabad | I13: Yes | J13: Wrong number
A14: LD0009 | B14: Amit Verma | D14: 9842710947 | F14: 07-Jan-2024 | G14: Converted | H14: Delhi | I14: No | J14: Follow up pending
A15: LD0111 | B15: Priya Mehta | C15: Google Ads | D15: 9294131869 | E15: priya.mehta67@gmail.com | F15: 18-Feb-2024 | G15: Converted | H15: Indore | I15: Yes | J15: Interested
A16: LD0069 | B16: Priya Mehta | C16: Referral | E16: priya.mehta30@gmail.com | F16: 06-Feb-2024 | G16: Converted | H16: BHOPAL | I16: No | J16: Price issue
A17: LD0155 | B17: Sneha Joshi | D17: 9242102499 | E17: sneha.joshi39@gmail.com | F17: 30-Mar-2024 | G17: Not Interested | H17: Jaipur | I17: No | J17: Call back tomorrow
A18: LD0377 | B18: Rahul Sharma | C18: IVR | E18: rahul.sharma84@gmail.com | F18: 26-Feb-2024 | G18: Lost | H18: Indore | I18: No | J18: Follow up pending
A19: LD0199 | B19: Priya Mehta | C19: Referral | D19: 9125674680 | F19: 02-Feb-2024 | G19: Converted | H19: Indore | J19: Wrong number
A20: LD0177 | B20: Rahul Sharma | C20: Organic | D20: 9038597703 | E20: rahul.sharma57@gmail.com | F20: 30-Mar-2024 | G20: Converted | H20: BHOPAL | I20: No | J20: Demo done
A21: LD0490 | B21: Amit Verma | C21: IVR | E21: amit.verma61@gmail.com | F21: 01-Feb-2024 | G21: Lost | H21: Bangalore | J21: Call back tomorrow
A22: LD0371 | B22: Karan Patel | D22: 9404499727 | E22: karan.patel98@gmail.com | F22: 10-Mar-2024 | G22: Converted | H22: Pune | I22: No | J22: Demo done
A23: LD0119 | B23: R.Singh | C23: Organic | D23: 9576627028 | F23: 26-Feb-2024 | G23: Converted | H23: BHOPAL | I23: No
A24: LD0379 | B24: Amit Verma | C24: Referral | D24: 9961586578 | E24: amit.verma88@gmail.com | F24: 02-Jun-2024 | G24: Converted | H24: Delhi | J24: Call back tomorrow
A25: LD0352 | B25: A.Gupta | C25: Google Ads | D25: 9504556238 | E25: anjali.gupta22@gmail.com | F25: 23-Jan-2024 | G25: Converted | H25: Pune | I25: No | J25: Not picking up
A26: LD0365 | B26: Sneha Joshi | C26: Organic | D26: 9074821759 | E26: sneha.joshi33@gmail.com | F26: 28-Feb-2024 | G26: Callback | H26: Jaipur | I26: Yes | J26: Demo done
A27: LD0408 | B27: Rohit Singh | C27: Referral | E27: rohit.singh46@gmail.com | F27: 29-Jan-2024 | G27: Not Interested | H27: Bangalore | I27: No | J27: Call back tomorrow
A28: LD0362 | B28: R.Sharma | C28: Google Ads | E28: rahul.sharma68@gmail.com | F28: 05-Mar-2024 | G28: Lost | H28: Jaipur | J28: Price issue
A29: LD0457 | B29: Divya Nair | C29: Google Ads | D29: 9368516048 | E29: divya.nair87@gmail.com | F29: 03-Feb-2024 | G29: Open | H29: Pune | I29: No | J29: Interested
A30: LD0341 | B30: Divya Nair | C30: Walk-in | D30: 9461200471 | E30: divya.nair50@gmail.com | F30: 28-Feb-2024 | G30: Converted | H30: Bangalore | I30: No | J30: Call back tomorrow
A31: LD0447 | B31: Anjali Gupta | C31: Referral | E31: anjali.gupta25@gmail.com | F31: 16-Jan-2024 | G31: Converted | H31: Mumbai | I31: Yes | J31: Closed deal
A32: LD0133 | B32: Sneha Joshi | C32: Meta Ads | D32: 9839335290 | F32: 17-Jan-2024 | G32: Lost | H32: Mumbai | I32: No | J32: Interested
A33: LD0482 | B33: Divya Nair | C33: Google Ads | E33: divya.nair58@gmail.com | F33: 03-May-2024 | G33: Open | H33: Hyderabad | I33: No | J33: Interested
A34: LD0417 | B34: Rahul Sharma | C34: Organic | D34: 9771159212 | E34: rahul.sharma92@gmail.com | F34: 11-Feb-2024 | G34: Not Interested | H34: Indore | I34: Yes | J34: Call back tomorrow
A35: LD0202 | B35: Sneha Joshi | C35: Meta Ads | D35: 9576615654 | E35: sneha.joshi61@gmail.com | F35: 09-Jan-2024 | G35: Converted | H35: Delhi | I35: No | J35: Closed deal
A36: LD0397 | B36: Amit Verma | D36: 9851656049 | E36: amit.verma28@gmail.com | F36: 20-Jan-2024 | G36: Callback | H36: Chennai | J36: Wrong number
A37: LD0430 | B37: Divya Nair | C37: IVR | D37: 9689980940 | E37: divya.nair44@gmail.com | F37: 14-Feb-2024 | G37: Lost | H37: Indore | I37: Yes | J37: Not picking up
A38: LD0324 | B38: Rahul Sharma | C38: Meta Ads | D38: 9675254599 | F38: 20-Mar-2024 | G38: Converted | H38: Indore | I38: No | J38: Follow up pending
A39: LD0152 | B39: Rohit Singh | C39: IVR | D39: 9561497840 | E39: rohit.singh1@gmail.com | F39: 27-Jan-2024 | G39: Callback | H39: Hyderabad | I39: Yes | J39: Closed deal
A40: LD0060 | B40: Priya Mehta | C40: Organic | E40: priya.mehta59@gmail.com | F40: 10-Jan-2024 | G40: Converted | H40: Indore | I40: Yes | J40: Call back tomorrow
...

Sheet Summary
A1: 📊 LEAD MANAGEMENT SUMMARY REPORT — 2024
A2: Real Estate CRM · 500 Total Leads · Jan–Dec 2024
A4: TOTAL LEADS | C4: CONVERTED | E4: CONV. RATE | G4: OPEN / CALLBACK | I4: LOST / NOT INT.
A5: =COUNTA('Cleaned Data'!G2:G501) -> 500 | C5: =COUNTIF('Cleaned Data'!G1:G505,"Converted") -> 184 | E5: =C5/A5 -> 0.368 | G5: =COUNTIFS('Cleaned Data'!G1:G501,"Callback")+COUNTIFS('Cleaned Data'!G1:G501,"Open") -> 195 | I5: =COUNTIFS('Cleaned Data'!G1:G501,"Lost")+COUNTIFS('Cleaned Data'!G1:G501,"Not interested") -> 121
A9: LEAD STATUS BREAKDOWN | F9: LEADS BY SOURCE
A10: Status | B10: Count | C10: Share % | D10: Visual Bar | E10: Notes | F10: Source | G10: Count | H10: Share % | I10: Bar
A11: Converted | B11: =COUNTIF('Cleaned Data'!G1:G511,"Converted") -> 184 | C11: =B11/$A$5 -> 0.368 | D11: =COUNTIF('Cleaned Data'!$J$2:$J$501,'Cleaned Data'!J485) -> 52 | E11: Closed deals | F11: Unknown | G11: =COUNTBLANK('Cleaned Data'!C1:C501) -> 99 | H11: =G11/500 -> 0.198 | I11: ██████ | J11: 0.202
A12: Open | B12: =COUNTIF('Cleaned Data'!G1:G512,"Open") -> 134 | C12: =B12/$A$5 -> 0.268 | D12: =COUNTIF('Cleaned Data'!$J$2:$J$501,E12) -> 0 | E12: Active pipeline | F12: Walk-in | G12: =COUNTIF('Cleaned Data'!$C$2:$C$501,F12) -> 75 | H12: =G12/500 -> 0.15 | I12: █████ | J12: 0.15
A13: Not Interested | B13: =COUNTIF('Cleaned Data'!G1:G513,"Not Interested") -> 61 | C13: =B13/$A$5 -> 0.122 | D13: =COUNTIF('Cleaned Data'!$J$2:$J$501,'Cleaned Data'!J498) -> 57 | E13: Dropped | F13: Referral | G13: =COUNTIF('Cleaned Data'!$C$2:$C$501,F13) -> 74 | H13: =G13/500 -> 0.148 | I13: ████ | J13: 0.146
A14: Callback | B14: =COUNTIF('Cleaned Data'!G1:G514,"Callback") -> 61 | C14: =B14/$A$5 -> 0.122 | D14: =COUNTIF('Cleaned Data'!$J$2:$J$501,'Cleaned Data'!J499) -> 53 | E14: Follow-up needed | F14: Google Ads | G14: =COUNTIF('Cleaned Data'!$C$2:$C$501,F14) -> 71 | H14: =G14/500 -> 0.142 | I14: ████ | J14: 0.14
A15: Lost | B15: =COUNTIF('Cleaned Data'!G1:G515,"Lost") -> 60 | C15: =B15/$A$5 -> 0.12 | D15: =COUNTIF('Cleaned Data'!$J$2:$J$501,'Cleaned Data'!J489) -> 52 | E15: Closed - lost | F15: Meta Ads | G15: =COUNTIF('Cleaned Data'!$C$2:$C$501,F15) -> 64 | H15: =G15/500 -> 0.128 | I15: ████ | J15: 0.128
F16: Organic | G16: =COUNTIF('Cleaned Data'!$C$2:$C$501,F16) -> 62 | H16: =G16/500 -> 0.124 | I16: ████ | J16: 0.124
F17: IVR | G17: =COUNTIF('Cleaned Data'!$C$2:$C$501,F17) -> 55 | H17: =G17/500 -> 0.11 | I17: ███ | J17: 0.11
A20: AGENT PERFORMANCE OVERVIEW
A21: Agent Name | B21: Total | C21: Converted | D21: Open | E21: Callback | F21: Not Interested | G21: Lost | H21: Conv % | I21: Rank
A22: Priya Mehta | B22: =COUNTIF('Cleaned Data'!$B$2:$B$501,A22) -> 72 | C22: =COUNTIFS('Cleaned Data'!$B$2:$B$501,Summary!$A22,'Cleaned Data'!$G$2:$G$501,Summary!C$21) -> 30 | D22: =COUNTIFS('Cleaned Data'!$B$2:$B$501,Summary!$A22,'Cleaned Data'!$G$2:$G$501,Summary!D$21) -> 18 | E22: =COUNTIFS('Cleaned Data'!$B$2:$B$501,Summary!$A22,'Cleaned Data'!$G$2:$G$501,Summary!E$21) -> 7 | F22: =COUNTIFS('Cleaned Data'!$B$2:$B$501,Summary!$A22,'Cleaned Data'!$G$2:$G$501,Summary!F$21) -> 9 | G22: =COUNTIFS('Cleaned Data'!$B$2:$B$501,Summary!$A22,'Cleaned Data'!$G$2:$G$501,Summary!G$21) -> 8 | H22: =$C22/$B22 -> 0.41666667 | I22: #1
A23: Divya Nair | B23: =COUNTIF('Cleaned Data'!$B$2:$B$501,A23) -> 65 | C23: =COUNTIFS('Cleaned Data'!$B$2:$B$501,Summary!$A23,'Cleaned Data'!$G$2:$G$501,Summary!C$21) -> 21 | D23: =COUNTIFS('Cleaned Data'!$B$2:$B$501,Summary!$A23,'Cleaned Data'!$G$2:$G$501,Summary!D$21) -> 22 | E23: =COUNTIFS('Cleaned Data'!$B$2:$B$501,Summary!$A23,'Cleaned Data'!$G$2:$G$501,Summary!E$21) -> 7 | F23: =COUNTIFS('Cleaned Data'!$B$2:$B$501,Summary!$A23,'Cleaned Data'!$G$2:$G$501,Summary!F$21) -> 9 | G23: =COUNTIFS('Cleaned Data'!$B$2:$B$501,Summary!$A23,'Cleaned Data'!$G$2:$G$501,Summary!G$21) -> 6 | H23: =$C23/$B23 -> 0.32307692 | I23: #2
A24: Sneha Joshi | B24: =COUNTIF('Cleaned Data'!$B$2:$B$501,A24) -> 62 | C24: =COUNTIFS('Cleaned Data'!$B$2:$B$501,Summary!$A24,'Cleaned Data'!$G$2:$G$501,Summary!C$21) -> 23 | D24: =COUNTIFS('Cleaned Data'!$B$2:$B$501,Summary!$A24,'Cleaned Data'!$G$2:$G$501,Summary!D$21) -> 15 | E24: =COUNTIFS('Cleaned Data'!$B$2:$B$501,Summary!$A24,'Cleaned Data'!$G$2:$G$501,Summary!E$21) -> 6 | F24: =COUNTIFS('Cleaned Data'!$B$2:$B$501,Summary!$A24,'Cleaned Data'!$G$2:$G$501,Summary!F$21) -> 10 | G24: =COUNTIFS('Cleaned Data'!$B$2:$B$501,Summary!$A24,'Cleaned Data'!$G$2:$G$501,Summary!G$21) -> 8 | H24: =$C24/$B24 -> 0.37096774 | I24: #3
A25: Karan Patel | B25: =COUNTIF('Cleaned Data'!$B$2:$B$501,A25) -> 60 | C25: =COUNTIFS('Cleaned Data'!$B$2:$B$501,Summary!$A25,'Cleaned Data'!$G$2:$G$501,Summary!C$21) -> 25 | D25: =COUNTIFS('Cleaned Data'!$B$2:$B$501,Summary!$A25,'Cleaned Data'!$G$2:$G$501,Summary!D$21) -> 12 | E25: =COUNTIFS('Cleaned Data'!$B$2:$B$501,Summary!$A25,'Cleaned Data'!$G$2:$G$501,Summary!E$21) -> 9 | F25: =COUNTIFS('Cleaned Data'!$B$2:$B$501,Summary!$A25,'Cleaned Data'!$G$2:$G$501,Summary!F$21) -> 6 | G25: =COUNTIFS('Cleaned Data'!$B$2:$B$501,Summary!$A25,'Cleaned Data'!$G$2:$G$501,Summary!G$21) -> 8 | H25: =$C25/$B25 -> 0.41666667 | I25: #4
A26: Rohit Singh | B26: =COUNTIF('Cleaned Data'!$B$2:$B$501,A26) -> 51 | C26: =COUNTIFS('Cleaned Data'!$B$2:$B$501,Summary!$A26,'Cleaned Data'!$G$2:$G$501,Summary!C$21) -> 16 | D26: =COUNTIFS('Cleaned Data'!$B$2:$B$501,Summary!$A26,'Cleaned Data'!$G$2:$G$501,Summary!D$21) -> 14 | E26: =COUNTIFS('Cleaned Data'!$B$2:$B$501,Summary!$A26,'Cleaned Data'!$G$2:$G$501,Summary!E$21) -> 8 | F26: =COUNTIFS('Cleaned Data'!$B$2:$B$501,Summary!$A26,'Cleaned Data'!$G$2:$G$501,Summary!F$21) -> 9 | G26: =COUNTIFS('Cleaned Data'!$B$2:$B$501,Summary!$A26,'Cleaned Data'!$G$2:$G$501,Summary!G$21) -> 4 | H26: =$C26/$B26 -> 0.31372549 | I26: #5
A27: Amit Verma | B27: =COUNTIF('Cleaned Data'!$B$2:$B$501,A27) -> 51 | C27: =COUNTIFS('Cleaned Data'!$B$2:$B$501,Summary!$A27,'Cleaned Data'!$G$2:$G$501,Summary!C$21) -> 17 | D27: =COUNTIFS('Cleaned Data'!$B$2:$B$501,Summary!$A27,'Cleaned Data'!$G$2:$G$501,Summary!D$21) -> 16 | E27: =COUNTIFS('Cleaned Data'!$B$2:$B$501,Summary!$A27,'Cleaned Data'!$G$2:$G$501,Summary!E$21) -> 6 | F27: =COUNTIFS('Cleaned Data'!$B$2:$B$501,Summary!$A27,'Cleaned Data'!$G$2:$G$501,Summary!F$21) -> 3 | G27: =COUNTIFS('Cleaned Data'!$B$2:$B$501,Summary!$A27,'Cleaned Data'!$G$2:$G$501,Summary!G$21) -> 9 | H27: =$C27/$B27 -> 0.33333333 | I27: #6
A28: Rahul Sharma | B28: =COUNTIF('Cleaned Data'!$B$2:$B$501,A28) -> 46 | C28: =COUNTIFS('Cleaned Data'!$B$2:$B$501,Summary!$A28,'Cleaned Data'!$G$2:$G$501,Summary!C$21) -> 15 | D28: =COUNTIFS('Cleaned Data'!$B$2:$B$501,Summary!$A28,'Cleaned Data'!$G$2:$G$501,Summary!D$21) -> 11 | E28: =COUNTIFS('Cleaned Data'!$B$2:$B$501,Summary!$A28,'Cleaned Data'!$G$2:$G$501,Summary!E$21) -> 7 | F28: =COUNTIFS('Cleaned Data'!$B$2:$B$501,Summary!$A28,'Cleaned Data'!$G$2:$G$501,Summary!F$21) -> 8 | G28: =COUNTIFS('Cleaned Data'!$B$2:$B$501,Summary!$A28,'Cleaned Data'!$G$2:$G$501,Summary!G$21) -> 5 | H28: =$C28/$B28 -> 0.32608696 | I28: #7
A29: Anjali Gupta | B29: =COUNTIF('Cleaned Data'!$B$2:$B$501,A29) -> 44 | C29: =COUNTIFS('Cleaned Data'!$B$2:$B$501,Summary!$A29,'Cleaned Data'!$G$2:$G$501,Summary!C$21) -> 12 | D29: =COUNTIFS('Cleaned Data'!$B$2:$B$501,Summary!$A29,'Cleaned Data'!$G$2:$G$501,Summary!D$21) -> 15 | E29: =COUNTIFS('Cleaned Data'!$B$2:$B$501,Summary!$A29,'Cleaned Data'!$G$2:$G$501,Summary!E$21) -> 5 | F29: =COUNTIFS('Cleaned Data'!$B$2:$B$501,Summary!$A29,'Cleaned Data'!$G$2:$G$501,Summary!F$21) -> 4 | G29: =COUNTIFS('Cleaned Data'!$B$2:$B$501,Summary!$A29,'Cleaned Data'!$G$2:$G$501,Summary!G$21) -> 8 | H29: =$C29/$B29 -> 0.27272727 | I29: #8
A30: R.Singh | B30: =COUNTIF('Cleaned Data'!$B$2:$B$501,A30) -> 18 | C30: =COUNTIFS('Cleaned Data'!$B$2:$B$501,Summary!$A30,'Cleaned Data'!$G$2:$G$501,Summary!C$21) -> 10 | D30: =COUNTIFS('Cleaned Data'!$B$2:$B$501,Summary!$A30,'Cleaned Data'!$G$2:$G$501,Summary!D$21) -> 2 | E30: =COUNTIFS('Cleaned Data'!$B$2:$B$501,Summary!$A30,'Cleaned Data'!$G$2:$G$501,Summary!E$21) -> 4 | F30: =COUNTIFS('Cleaned Data'!$B$2:$B$501,Summary!$A30,'Cleaned Data'!$G$2:$G$501,Summary!F$21) -> 1 | G30: =COUNTIFS('Cleaned Data'!$B$2:$B$501,Summary!$A30,'Cleaned Data'!$G$2:$G$501,Summary!G$21) -> 1 | H30: =$C30/$B30 -> 0.55555556 | I30: #9
A31: A.Gupta | B31: =COUNTIF('Cleaned Data'!$B$2:$B$501,A31) -> 15 | C31: =COUNTIFS('Cleaned Data'!$B$2:$B$501,Summary!$A31,'Cleaned Data'!$G$2:$G$501,Summary!C$21) -> 7 | D31: =COUNTIFS('Cleaned Data'!$B$2:$B$501,Summary!$A31,'Cleaned Data'!$G$2:$G$501,Summary!D$21) -> 5 | E31: =COUNTIFS('Cleaned Data'!$B$2:$B$501,Summary!$A31,'Cleaned Data'!$G$2:$G$501,Summary!E$21) -> 1 | F31: =COUNTIFS('Cleaned Data'!$B$2:$B$501,Summary!$A31,'Cleaned Data'!$G$2:$G$501,Summary!F$21) -> 0 | G31: =COUNTIFS('Cleaned Data'!$B$2:$B$501,Summary!$A31,'Cleaned Data'!$G$2:$G$501,Summary!G$21) -> 2 | H31: =$C31/$B31 -> 0.46666667 | I31: #10
A32: A.Verma | B32: =COUNTIF('Cleaned Data'!$B$2:$B$501,A32) -> 10 | C32: =COUNTIFS('Cleaned Data'!$B$2:$B$501,Summary!$A32,'Cleaned Data'!$G$2:$G$501,Summary!C$21) -> 5 | D32: =COUNTIFS('Cleaned Data'!$B$2:$B$501,Summary!$A32,'Cleaned Data'!$G$2:$G$501,Summary!D$21) -> 2 | E32: =COUNTIFS('Cleaned Data'!$B$2:$B$501,Summary!$A32,'Cleaned Data'!$G$2:$G$501,Summary!E$21) -> 1 | F32: =COUNTIFS('Cleaned Data'!$B$2:$B$501,Summary!$A32,'Cleaned Data'!$G$2:$G$501,Summary!F$21) -> 2 | G32: =COUNTIFS('Cleaned Data'!$B$2:$B$501,Summary!$A32,'Cleaned Data'!$G$2:$G$501,Summary!G$21) -> 0 | H32: =$C32/$B32 -> 0.5 | I32: #11
A33: R.Sharma | B33: =COUNTIF('Cleaned Data'!$B$2:$B$501,A33) -> 6 | C33: =COUNTIFS('Cleaned Data'!$B$2:$B$501,Summary!$A33,'Cleaned Data'!$G$2:$G$501,Summary!C$21) -> 3 | D33: =COUNTIFS('Cleaned Data'!$B$2:$B$501,Summary!$A33,'Cleaned Data'!$G$2:$G$501,Summary!D$21) -> 2 | E33: =COUNTIFS('Cleaned Data'!$B$2:$B$501,Summary!$A33,'Cleaned Data'!$G$2:$G$501,Summary!E$21) -> 0 | F33: =COUNTIFS('Cleaned Data'!$B$2:$B$501,Summary!$A33,'Cleaned Data'!$G$2:$G$501,Summary!F$21) -> 0 | G33: =COUNTIFS('Cleaned Data'!$B$2:$B$501,Summary!$A33,'Cleaned Data'!$G$2:$G$501,Summary!G$21) -> 1 | H33: =$C33/$B33 -> 0.5 | I33: #12
A36: LEADS BY CITY | F36: MONTHLY LEAD TREND
A37: City | B37: Leads | C37: Share % | D37: Bar | F37: Month | G37: Total | H37: Converted | I37: Conv % | J37: Trend
A38: Indore | B38: =COUNTIF('Cleaned Data'!$H$2:$H$501,Summary!$A38) -> 70 | C38: =$B38/500 -> 0.14 | D38: ███████ | E38: 0.15350877 | F38: Jan 2024 | G38: 168 | H38: 60 | I38: 35.7% | J38: 📈
A39: Delhi | B39: =COUNTIF('Cleaned Data'!$H$2:$H$501,Summary!$A39) -> 64 | C39: =$B39/500 -> 0.128 | D39: ██████ | E39: 0.14035088 | F39: Feb 2024 | G39: 159 | H39: 64 | I39: 40.3% | J39: 📉
A40: Pune | B40: =COUNTIF('Cleaned Data'!$H$2:$H$501,Summary!$A40) -> 61 | C40: =$B40/500 -> 0.122 | D40: ██████ | E40: 0.13377193 | F40: Mar 2024 | G40: 142 | H40: 53 | I40: 37.3% | J40: 📉
A41: Hyderabad | B41: =COUNTIF('Cleaned Data'!$H$2:$H$501,Summary!$A41) -> 56 | C41: =$B41/500 -> 0.112 | D41: █████ | E41: 0.12280702
A42: Bangalore | B42: =COUNTIF('Cleaned Data'!$H$2:$H$501,Summary!$A42) -> 55 | C42: =$B42/500 -> 0.11 | D42: █████ | E42: 0.12061404
A43: Jaipur | B43: =COUNTIF('Cleaned Data'!$H$2:$H$501,Summary!$A43) -> 53 | C43: =$B43/500 -> 0.106 | D43: █████ | E43: 0.11622807
A44: Mumbai | B44: =COUNTIF('Cleaned Data'!$H$2:$H$501,Summary!$A44) -> 52 | C44: =$B44/500 -> 0.104 | D44: █████ | E44: 0.11403509
A45: Chennai | B45: =COUNTIF('Cleaned Data'!$H$2:$H$501,Summary!$A45) -> 45 | C45: =$B45/500 -> 0.09 | D45: ████ | E45: 0.098684211
A46: BHOPAL | B46: =COUNTIF(Table1[City],'Cleaned Data'!H467) -> 44 | C46: =$B46/500 -> 0.088

Sheet Dashboard & Pivot table
A1: 📊 LEAD MANAGEMENT DASHBOARD REPORT — 2024
Q3: Total Leads | R3: Total Leads
Y5: Row Labels | Z5: Count of Lead Source | AC5: Row Labels | AD5: Count of Status | AH5: Row Labels | AI5: Count of Lead Source
R6: Converted & Rate | Y6: Google Ads | Z6: 71 | AC6: Callback | AD6: 61 | AH6: BHOPAL | AI6: 33
Q7: =Summary!C5 -> 184 | S7: =Q7/Summary!A5 -> 0.368 | Y7: IVR | Z7: 55 | AC7: Converted | AD7: 184 | AH7: Chennai | AI7: 36
Y8: Meta Ads | Z8: 64 | AC8: Lost | AD8: 60 | AH8: Mumbai | AI8: 39
Y9: Organic | Z9: 62 | AC9: Not Interested | AD9: 61 | AH9: Jaipur | AI9: 42
Y10: Referral | Z10: 73 | AC10: Open | AD10: 134 | AH10: Bangalore | AI10: 44
Y11: Walk-in | Z11: 75 | AC11: Grand Total | AD11: 500 | AH11: Hyderabad | AI11: 46
Y12: (blank) | AH12: Pune | AI12: 49
Y13: Grand Total | Z13: 400 | AH13: Delhi | AI13: 55
AH14: Indore | AI14: 56
AH15: Grand Total | AI15: 400
Y18: Count of Status | Z18: Column Labels
Y19: Row Labels | Z19: Callback | AA19: Converted | AB19: Lost | AC19: Not Interested | AD19: Open | AE19: Grand Total | AH19: Month | AI19: Total | AJ19: Converted
Y20: A.Gupta | Z20: 1 | AA20: 7 | AB20: 2 | AD20: 5 | AE20: 15 | AH20: Jan 2024 | AI20: 168 | AJ20: 60
Y21: A.Verma | Z21: 1 | AA21: 5 | AC21: 2 | AD21: 2 | AE21: 10 | AH21: Feb 2024 | AI21: 159 | AJ21: 64
Y22: Amit Verma | Z22: 6 | AA22: 17 | AB22: 9 | AC22: 3 | AD22: 16 | AE22: 51 | AH22: Mar 2024 | AI22: 142 | AJ22: 53
Y23: Anjali Gupta | Z23: 5 | AA23: 12 | AB23: 8 | AC23: 4 | AD23: 15 | AE23: 44
Y24: Divya Nair | Z24: 7 | AA24: 21 | AB24: 6 | AC24: 9 | AD24: 22 | AE24: 65
Y25: Karan Patel | Z25: 9 | AA25: 25 | AB25: 8 | AC25: 6 | AD25: 12 | AE25: 60
Y26: Priya Mehta | Z26: 7 | AA26: 30 | AB26: 8 | AC26: 9 | AD26: 18 | AE26: 72
Y27: R.Sharma | AA27: 3 | AB27: 1 | AD27: 2 | AE27: 6
Y28: R.Singh | Z28: 4 | AA28: 10 | AB28: 1 | AC28: 1 | AD28: 2 | AE28: 18
Y29: Rahul Sharma | Z29: 7 | AA29: 15 | AB29: 5 | AC29: 8 | AD29: 11 | AE29: 46
Y30: Rohit Singh | Z30: 8 | AA30: 16 | AB30: 4 | AC30: 9 | AD30: 14 | AE30: 51
Y31: Sneha Joshi | Z31: 6 | AA31: 23 | AB31: 8 | AC31: 10 | AD31: 15 | AE31: 62
Y32: Grand Total | Z32: 61 | AA32: 184 | AB32: 60 | AC32: 61 | AD32: 134 | AE32: 500
